Workbook

Sheet DATI
A1: LOB | B1: Rgt/Cal/QC/Cons | C1: Lotto 1 - Area Siero | D1: Assay name | E1: LN ABBOTT | F1: LN ABBOTT AGGIORNATI | G1: Descrizione commerciale | H1: KIT | I1: Conf.to | J1: Test (tot) medi/mm ALINK | L1: Test TOT MEDI/MESE Aggiustati | M1: # Kit/Mese
A2: =IF(_xlfn.NUMBERVALUE(SEARCH("Alinity c",G2)),"CC","IA") | B2: RGT | C2: ACIDI BILIARI | D2: Bile Acids | E2: 8P5722 | G2: Alinity c Acidi biliari Reagente | H2: 200 | I2: 4x50 | J2: =VLOOKUP(D2,[1]Sheet2!$A$5:$E$146,5,FALSE()) | L2: 200 | M2: =L2/H2
A3: =IF(_xlfn.NUMBERVALUE(SEARCH("Alinity c",G3)),"CC","IA") | B3: RGT | C3: ACIDO LATTICO | E3: 4U2620 | G3: Alinity c Acido Lattico Reagente | H3: 400 | I3: 4x100 | J3: =VLOOKUP(D3,[1]Sheet2!$A$5:$E$146,5,FALSE()) | L3: … | M3: ….
A4: =IF(_xlfn.NUMBERVALUE(SEARCH("Alinity c",G4)),"CC","IA") | B4: RGT | C4: ACIDO VALPROICO | D4: Valproic | E4: 9P9220 | G4: Alinity c Acido Valproico Reagente | H4: 200 | I4: 2x100 | J4: =VLOOKUP(D4,[1]Sheet2!$A$5:$E$146,5,FALSE()) | L4: 200 | M4: =L4/H4
A5: =IF(_xlfn.NUMBERVALUE(SEARCH("Alinity c",G5)),"CC","IA") | B5: RGT | C5: ALBUMINA | G5: Alinity c Albumina BCG 2 Reagente | H5: 3120 | I5: 4x780
A6: =IF(_xlfn.NUMBERVALUE(SEARCH("Alinity c",G6)),"CC","IA") | B6: RGT | D6: AlbBCG2 | E6: 4U3020 | G6: Alinity c Albumina BCG 2 Reagente | H6: 1044 | I6: 4x261 | J6: =VLOOKUP(D6,[1]Sheet2!$A$5:$E$146,5,FALSE()) | L6: 2000 | M6: =L6/H6
A7: =IF(_xlfn.NUMBERVALUE(SEARCH("Alinity c",G7)),"CC","IA") | B7: RGT | C7: ALBUMINA URINARIA | D7: Microalb | E7: 8P0424 | G7: Alinity c Microalbumina Reagente | H7: 640 | I7: 2x320 | J7: =VLOOKUP(D7,[1]Sheet2!$A$5:$E$146,5,FALSE()) | L7: 1900 | M7: =L7/H7
A8: =IF(_xlfn.NUMBERVALUE(SEARCH("Alinity c",G8)),"CC","IA") | B8: RGT | C8: ALCOLEMIA | D8: Ethanol | E8: 8P4130 | G8: Alinity c Etanolo Reagente | H8: 400 | I8: 4x100 | J8: =VLOOKUP(D8,[1]Sheet2!$A$5:$E$146,5,FALSE()) | L8: 300 | M8: =L8/H8
A9: =IF(_xlfn.NUMBERVALUE(SEARCH("Alinity c",G9)),"CC","IA") | B9: RGT | C9: ALFA-1-ANTITRIPSINA | D9: a1AT | E9: 1R0720 | G9: Alinity c Alfa-1 Antitripsina Reagente | H9: 200 | I9: 2x100 | J9: =VLOOKUP(D9,[1]Sheet2!$A$5:$E$146,5,FALSE()) | L9: 150 | M9: =L9/H9
A10: =IF(_xlfn.NUMBERVALUE(SEARCH("Alinity c",G10)),"CC","IA") | B10: RGT | C10: ALFA-1-GLIC. ACIDA | D10: a1AGP | E10: 1R0820 | G10: Alinity c Alfa-1 Glicoproteina Reagente | H10: 200 | I10: 2x100 | J10: =VLOOKUP(D10,[1]Sheet2!$A$5:$E$146,5,FALSE()) | L10: 150 | M10: =L10/H10
A11: IA | B11: RGT | C11: ALFA-FETOPROTEINA | D11: AFP | E11: 7P9020 | G11: Alinity i AFP Reagente | H11: 200 | I11: 2x100 | J11: =VLOOKUP(D11,[1]Sheet2!$A$5:$E$146,5,FALSE()) | L11: 500 | M11: =L11/H11
A12: =IF(_xlfn.NUMBERVALUE(SEARCH("Alinity c",G12)),"CC","IA") | B12: RGT | C12: AMFETAMINA su Urina | D12: AmpSQ | E12: 9P4520 | G12: Alinity c Anfetamina/Metanfetamine Reagente | H12: 400 | I12: 2x200 | J12: =VLOOKUP(D12,[1]Sheet2!$A$5:$E$146,5,FALSE()) | L12: 400 | M12: =L12/H12
A13: IA | B13: RGT | C13: AMH ° - NON RICHIESTO
A14: =IF(_xlfn.NUMBERVALUE(SEARCH("Alinity c",G14)),"CC","IA") | B14: RGT | C14: AMILASI | D14: AMY2F | E14: 4T8520 | G14: Alinity c Amilasi 2 Reagente | H14: 640 | I14: 4x160 | J14: =VLOOKUP(D14,[1]Sheet2!$A$5:$E$146,5,FALSE()) | L14: 1500 | M14: =L14/H14
A15: =IF(_xlfn.NUMBERVALUE(SEARCH("Alinity c",G15)),"CC","IA") | B15: RGT | C15: AMILASI PANCREATICA | D15: P Amylase | E15: 1R0422 | G15: Alinity c Amilasi Pancreatica Reagente | H15: 200 | I15: 2x100 | J15: =VLOOKUP(D15,[1]Sheet2!$A$5:$E$146,5,FALSE()) | L15: 3500 | M15: =L15/H15
A16: =IF(_xlfn.NUMBERVALUE(SEARCH("Alinity c",G16)),"CC","IA") | B16: RGT | C16: AMMONIEMIA | D16: Ammonia | E16: 8P2220 | G16: Alinity c Ammonio Reagente | H16: 200 | I16: 2x100 | J16: =VLOOKUP(D16,[1]Sheet2!$A$5:$E$146,5,FALSE()) | L16: 400 | M16: =L16/H16
A17: IA | B17: RGT | C17: ANTI HCV | D17: Anti-HCVII | E17: 8P0633 | F17: 06T7932 | G17: Alinity i Anti-HCV Reagente--> HCV Next | H17: 1000 | I17: 2x500 | J17: =VLOOKUP(D17,[1]Sheet2!$A$5:$E$146,5,FALSE()) | L17: 2000 | M17: =L17/H17
A18: IA | B18: RGT | G18: Alinity i Anti-HCV Reagente | H18: 200 | I18: 2x100
A19: IA | B19: RGT | C19: ANTI- TIREOGLOBULINA | D19: Anti-Tg | E19: 9P3420 | G19: Alinity i Anti Tg Reagente | H19: 200 | I19: 2x100 | J19: =VLOOKUP(D19,[1]Sheet2!$A$5:$E$146,5,FALSE()) | L19: 900 | M19: =L19/H19
A20: IA | B20: RGT | C20: ANTI-PEROSSIDASI | D20: Anti-TPO | E20: 9P3522 | G20: Alinity i Anti TPO Reagente | H20: 200 | I20: 2x100 | J20: =VLOOKUP(D20,[1]Sheet2!$A$5:$E$146,5,FALSE()) | L20: 900 | M20: =L20/H20
A21: =IF(_xlfn.NUMBERVALUE(SEARCH("Alinity c",G21)),"CC","IA") | B21: RGT | C21: APOLIPOPROT A | D21: APOA1 | E21: 9P4624 | G21: Alinity c Apolipoproteina A1 Reagente | H21: 190 | I21: 2x95 | J21: =VLOOKUP(D21,[1]Sheet2!$A$5:$E$146,5,FALSE()) | L21: 150 | M21: =L21/H21
A22: =IF(_xlfn.NUMBERVALUE(SEARCH("Alinity c",G22)),"CC","IA") | B22: RGT | C22: APOLIPOPROT B | D22: APOB | E22: 9P4724 | G22: Alinity c Apolipoproteina B Reagente | H22: 190 | I22: 2x95 | J22: =VLOOKUP(D22,[1]Sheet2!$A$5:$E$146,5,FALSE()) | L22: 200 | M22: =L22/H22
A23: =IF(_xlfn.NUMBERVALUE(SEARCH("Alinity c",G23)),"CC","IA") | B23: RGT | C23: APTOGLOBINA | D23: Haptoglob | E23: 9P5924 | G23: Alinity c Aptoglobina Reagente | H23: 180 | I23: 2x90 | J23: =VLOOKUP(D23,[1]Sheet2!$A$5:$E$146,5,FALSE()) | L23: 200 | M23: =L23/H23
A24: =IF(_xlfn.NUMBERVALUE(SEARCH("Alinity c",G24)),"CC","IA") | B24: RGT | C24: AZOTEMIA | D24: Urea/UreaU | E24: 8P1630 | G24: Alinity c Azoto Ureico Reagente | H24: 13000 | I24: 10x1300 | J24: 13800 | L24: 15000 | M24: =L24/H24
A25: =IF(_xlfn.NUMBERVALUE(SEARCH("Alinity c",G25)),"CC","IA") | B25: RGT | G25: Alinity c Azoto Ureico Reagente | H25: 4000 | I25: 10x400
A26: =IF(_xlfn.NUMBERVALUE(SEARCH("Alinity c",G26)),"CC","IA") | B26: RGT | C26: BENZODIAZEPINE (U) | D26: BenzSQ | E26: 9P5220 | G26: Alinity c Benzodiazepine Reagente | H26: 500 | I26: 2x250 | J26: =VLOOKUP(D26,[1]Sheet2!$A$5:$E$146,5,FALSE()) | L26: 500 | M26: =L26/H26
A27: IA | B27: RGT | C27: Beta HCG | D27: B-hCG | E27: 7P5120 | G27: Alinity i Total β-hCG Reagente | H27: 200 | I27: 2x100 | J27: =VLOOKUP(D27,[1]Sheet2!$A$5:$E$146,5,FALSE()) | L27: 600 | M27: =L27/H27
A28: =IF(_xlfn.NUMBERVALUE(SEARCH("Alinity c",G28)),"CC","IA") | B28: RGT | C28: BETA2-MICROGLOBULINA | D28: B2M | E28: 1R0920 | G28: Alinity c B2-Microglobulina Reagente | H28: 200 | I28: 2x100 | J28: =VLOOKUP(D28,[1]Sheet2!$A$5:$E$146,5,FALSE()) | L28: 400 | M28: =L28/H28
A29: =IF(_xlfn.NUMBERVALUE(SEARCH("Alinity c",G29)),"CC","IA") | B29: RGT | C29: BILIRUBINA DIRETTA | D29: Bili D | E29: 7P9720 | G29: Alinity c Bilirubina Diretta Reagente | H29: 1440 | I29: 4x360 | J29: =VLOOKUP(D29,[1]Sheet2!$A$5:$E$146,5,FALSE()) | L29: 10000 | M29: =L29/H29
A30: =IF(_xlfn.NUMBERVALUE(SEARCH("Alinity c",G30)),"CC","IA") | B30: RGT | C30: BILIRUBINA TOTALE | D30: TBili2 | E30: 4U0520 | G30: Alinity c Bilirubina Totale 2 Reagente | H30: 3500 | I30: 10x350 | J30: =VLOOKUP(D30,[1]Sheet2!$A$5:$E$146,5,FALSE()) | L30: 10000 | M30: =L30/H30
A31: IA | B31: RGT | C31: BNP/NT-proBNP | D31: BNP | E31: 8P2430 | G31: Alinity i BNP Reagente | H31: 1000 | I31: 2x500 | J31: =VLOOKUP(D31,[1]Sheet2!$A$5:$E$146,5,FALSE()) | L31: 1800 | M31: =L31/H31
A32: IA | B32: RGT | G32: Alinity i BNP Reagente | H32: 200 | I32: 2x100
A33: =IF(_xlfn.NUMBERVALUE(SEARCH("Alinity c",G33)),"CC","IA") | B33: RGT | C33: BUPRENORFINA (U) | D33: BUP SQ | E33: 4Z4220 | G33: Alinity c Buprenorfina Reagente | H33: 200 | I33: 1x200 | J33: =VLOOKUP(D33,[1]Sheet2!$A$5:$E$146,5,FALSE()) | L33: 300 | M33: =L33/H33
A34: IA | B34: RGT | C34: C PEPTIDE | D34: C-Peptide | E34: 9P3620 | G34: Alinity i C-Peptide Reagente | H34: 200 | I34: 2x100 | J34: =VLOOKUP(D34,[1]Sheet2!$A$5:$E$146,5,FALSE()) | L34: 150 | M34: =L34/H34
A35: IA | B35: RGT | C35: CA 125 | D35: CA 125 II | E35: 8P4920 | G35: Alinity i CA 125 II Reagente | H35: 200 | I35: 2x100 | J35: =VLOOKUP(D35,[1]Sheet2!$A$5:$E$146,5,FALSE()) | L35: 600 | M35: =L35/H35
A36: IA | B36: RGT | C36: CA 15.3 | D36: CA 15-3 | E36: 8P5120 | G36: Alinity i CA 15-3 Reagente | H36: 200 | I36: 2x100 | J36: =VLOOKUP(D36,[1]Sheet2!$A$5:$E$146,5,FALSE()) | L36: 600 | M36: =L36/H36
A37: IA | B37: RGT | C37: CA 19.9 | D37: CA19-9XR | E37: 8P3230 | G37: Alinity i CA 19-9XR Reagente | H37: 1000 | I37: 2x500 | J37: =VLOOKUP(D37,[1]Sheet2!$A$5:$E$146,5,FALSE()) | L37: 600 | M37: =L37/H37
A38: =IF(_xlfn.NUMBERVALUE(SEARCH("Alinity c",G38)),"CC","IA") | B38: RGT | C38: CALCIO | D38: CaC2-CaC2-U | E38: 4T8730 | G38: Alinity c Calcio 2 Reagente | H38: 5160 | I38: 4x1290 | J38: =VLOOKUP(D38,[1]Sheet2!$A$5:$E$146,5,FALSE()) | L38: 10000 | M38: =L38/H38
A39: =IF(_xlfn.NUMBERVALUE(SEARCH("Alinity c",G39)),"CC","IA") | B39: RGT | G39: Alinity c Calcio 2 Reagente | H39: 1560 | I39: 4x390
A40: =IF(_xlfn.NUMBERVALUE(SEARCH("Alinity c",G40)),"CC","IA") | B40: RGT | C40: CANNABINOIDI (U) | D40: THC1SQ | E40: 9P5420 | G40: Alinity c Cannabinoidi Reagente | H40: 400 | I40: 2x200 | J40: =VLOOKUP(D40,[1]Sheet2!$A$5:$E$146,5,FALSE()) | L40: 800 | M40: =L40/H40
...

Sheet TEST_COUNT_PRIMI 3 MESI
A1: ASSAY_NUMBER | B1: - tutto -
A3: Sum of TOT/MM | B3: MODULE_TYPE
A4: ASSAY_NAME | B4: Alinity c | C4: Alinity i | D4: (vuoto) | E4: Totale Risultato
A5: a1AGP | B5: 102 | E5: 102
A6: a1AT | B6: 118.66667 | E6: 118.66667
A7: A-ALT | B7: 15328 | E7: 15328
A8: A-AST | B8: 14228.333 | E8: 14228.333
A9: AFP | C9: 392 | E9: 392
A10: AlbBCG2 | B10: 1439 | E10: 1439
A11: AlkP2F | B11: 3508 | E11: 3508
A12: Ammonia | B12: 302 | E12: 302
A13: AmpSQ | B13: 341.66667 | E13: 341.66667
A14: AMY2F | B14: 1310.3333 | E14: 1310.3333
A15: AMY2-UF | B15: 203.33333 | E15: 203.33333
A16: Anti-HBc | C16: 515 | E16: 515
A17: Anti-HBc M | C17: 417.66667 | E17: 417.66667
A18: Anti-HBe | C18: 416.33333 | E18: 416.33333
A19: AntiHBsdil | C19: 1334.3333 | E19: 1334.3333
A20: Anti-HCVII | C20: 1598.3333 | E20: 1598.3333
A21: Anti-Tg | C21: 767.33333 | E21: 767.33333
A22: Anti-TPO | C22: 730.33333 | E22: 730.33333
A23: APOA1 | B23: 130.66667 | E23: 130.66667
A24: APOB | B24: 196.66667 | E24: 196.66667
A25: ASO | B25: 170.66667 | E25: 170.66667
A26: B2M | B26: 290.33333 | E26: 290.33333
A27: BarbSQ | B27: 98.333333 | E27: 98.333333
A28: BenzSQ | B28: 420 | E28: 420
A29: B-hCG | C29: 515.66667 | E29: 515.66667
A30: Bile Acids | B30: 159.66667 | E30: 159.66667
A31: Bili D | B31: 9057.3333 | E31: 9057.3333
A32: BNP | C32: 1566.6667 | E32: 1566.6667
A33: BUP SQ | B33: 210.66667 | E33: 210.66667
A34: C3 | B34: 236 | E34: 236
A35: C4 | B35: 239.66667 | E35: 239.66667
A36: CA 125 II | C36: 441.66667 | E36: 441.66667
A37: CA 15-3 | C37: 491.66667 | E37: 491.66667
A38: CA19-9XR | C38: 480.33333 | E38: 480.33333
A39: CaC2 | B39: 10161.667 | E39: 10161.667
A40: CaC2-U | B40: 279 | E40: 279
A41: Carb | B41: 166.66667 | E41: 166.66667
...

Sheet DPCache_Instrument Summary (1)
A1: MODULE_SERIAL | B1: MODULE_TYPE | C1: ASSAY_NAME | D1: ASSAY_NUMBER | E1: PATIENTS_ATTEMPTED | F1: PATIENTS_COMPLETED | G1: PATIENTS_RETESTED | H1: PATIENTS_DILUTED | I1: CALIBRATORS_ATTEMPTED | J1: CONTROLS_ATTEMPTED | K1: CONTROLS_COMPLETED | L1: TOTAL_ATTEMPTED | M1: TOT/MM
A2: AC04860 | B2: Alinity c | C2: a1AGP | D2: 1912 | E2: 41 | F2: 40 | G2: 3 | H2: 2 | I2: 60 | J2: 205 | K2: 195 | L2: 306 | M2: 102
A3: AC04860 | B3: Alinity c | C3: a1AT | D3: 1901 | E3: 120 | F3: 112 | G3: 5 | H3: 0 | I3: 36 | J3: 200 | K3: 190 | L3: 356 | M3: 118.66667
A4: AC04860 | B4: Alinity c | C4: A-ALT | D4: 1032 | E4: 16189 | F4: 13756 | G4: 1947 | H4: 22 | I4: 24 | J4: 422 | K4: 390 | L4: 16635 | M4: 5545
A5: AC04860 | B5: Alinity c | C5: A-ALT | D5: 1032 | E5: 11832 | F5: 11362 | G5: 386 | H5: 67 | I5: 15 | J5: 355 | K5: 337 | L5: 12202 | M5: 4067.3333
A6: AC04860 | B6: Alinity c | C6: A-ALT | D6: 1032 | E6: 16759 | F6: 14861 | G6: 1412 | H6: 50 | I6: 15 | J6: 373 | K6: 361 | L6: 17147 | M6: 5715.6667
A7: AC04860 | B7: Alinity c | C7: A-AST | D7: 1046 | E7: 14698 | F7: 12646 | G7: 1620 | H7: 1 | I7: 15 | J7: 388 | K7: 357 | L7: 15101 | M7: 5033.6667
A8: AC04860 | B8: Alinity c | C8: A-AST | D8: 1046 | E8: 11492 | F8: 11020 | G8: 374 | H8: 8 | I8: 18 | J8: 344 | K8: 325 | L8: 11854 | M8: 3951.3333
A9: AC04860 | B9: Alinity c | C9: A-AST | D9: 1046 | E9: 15362 | F9: 13739 | G9: 1191 | H9: 10 | I9: 15 | J9: 353 | K9: 342 | L9: 15730 | M9: 5243.3333
A10: AI22529 | B10: Alinity i | C10: AFP | D10: 10 | E10: 781 | F10: 686 | G10: 57 | H10: 5 | I10: 24 | J10: 371 | K10: 291 | L10: 1176 | M10: 392
A11: AC04860 | B11: Alinity c | C11: AlbBCG2 | D11: 1400 | E11: 1130 | F11: 1001 | G11: 104 | H11: 0 | I11: 18 | J11: 221 | K11: 204 | L11: 1369 | M11: 456.33333
A12: AC04860 | B12: Alinity c | C12: AlbBCG2 | D12: 1400 | E12: 1375 | F12: 1314 | G12: 58 | H12: 0 | I12: 24 | J12: 182 | K12: 176 | L12: 1581 | M12: 527
A13: AC04860 | B13: Alinity c | C13: AlbBCG2 | D13: 1400 | E13: 1127 | F13: 1002 | G13: 94 | H13: 0 | I13: 24 | J13: 216 | K13: 211 | L13: 1367 | M13: 455.66667
... A291: AI22529 | B291: Alinity i | C291: VitaminB12 | D291: 654 | E291: 99 | F291: 84 | G291: 13 | H291: 3 | I291: 60 | J291: 99 | K291: 89 | L291: 258 | M291: 86

Sheet GIACENZA_REALE
A1: Codice | B1: Descrizione | C1: Kit disponibili | D1: Scadenza

Sheet ORDINE_MESE
A1: Codice | B1: Descrizione | C1: Kit/mese | D1: Kit disponibili | E1: Copertura (mesi) | F1: Kit da ordinare
A2: =DATI!A2 | B2: =DATI!B2 | C2: =DATI!H2 | D2: =SE.ERRORE(CERCA.X(A2;GIACENZA_REALE!A:A;GIACENZA_REALE!C:C);0) | E2: =SE(C2=0;"";D2/C2) | F2: =MAX(0;ARROTONDA.ECCESSO(C2-D2;1))
A3: =DATI!A3 | B3: =DATI!B3 | C3: =DATI!H3 | D3: =SE.ERRORE(CERCA.X(A3;GIACENZA_REALE!A:A;GIACENZA_REALE!C:C);0) | E3: =SE(C3=0;"";D3/C3) | F3: =MAX(0;ARROTONDA.ECCESSO(C3-D3;1))
A4: =DATI!A4 | B4: =DATI!B4 | C4: =DATI!H4 | D4: =SE.ERRORE(CERCA.X(A4;GIACENZA_REALE!A:A;GIACENZA_REALE!C:C);0) | E4: =SE(C4=0;"";D4/C4) | F4: =MAX(0;ARROTONDA.ECCESSO(C4-D4;1))
A5: =DATI!A5 | B5: =DATI!B5 | C5: =DATI!H5 | D5: =SE.ERRORE(CERCA.X(A5;GIACENZA_REALE!A:A;GIACENZA_REALE!C:C);0) | E5: =SE(C5=0;"";D5/C5) | F5: =MAX(0;ARROTONDA.ECCESSO(C5-D5;1))
A6: =DATI!A6 | B6: =DATI!B6 | C6: =DATI!H6 | D6: =SE.ERRORE(CERCA.X(A6;GIACENZA_REALE!A:A;GIACENZA_REALE!C:C);0) | E6: =SE(C6=0;"";D6/C6) | F6: =MAX(0;ARROTONDA.ECCESSO(C6-D6;1))
A7: =DATI!A7 | B7: =DATI!B7 | C7: =DATI!H7 | D7: =SE.ERRORE(CERCA.X(A7;GIACENZA_REALE!A:A;GIACENZA_REALE!C:C);0) | E7: =SE(C7=0;"";D7/C7) | F7: =MAX(0;ARROTONDA.ECCESSO(C7-D7;1))
A8: =DATI!A8 | B8: =DATI!B8 | C8: =DATI!H8 | D8: =SE.ERRORE(CERCA.X(A8;GIACENZA_REALE!A:A;GIACENZA_REALE!C:C);0) | E8: =SE(C8=0;"";D8/C8) | F8: =MAX(0;ARROTONDA.ECCESSO(C8-D8;1))
A9: =DATI!A9 | B9: =DATI!B9 | C9: =DATI!H9 | D9: =SE.ERRORE(CERCA.X(A9;GIACENZA_REALE!A:A;GIACENZA_REALE!C:C);0) | E9: =SE(C9=0;"";D9/C9) | F9: =MAX(0;ARROTONDA.ECCESSO(C9-D9;1))
A10: =DATI!A10 | B10: =DATI!B10 | C10: =DATI!H10 | D10: =SE.ERRORE(CERCA.X(A10;GIACENZA_REALE!A:A;GIACENZA_REALE!C:C);0) | E10: =SE(C10=0;"";D10/C10) | F10: =MAX(0;ARROTONDA.ECCESSO(C10-D10;1))
A11: =DATI!A11 | B11: =DATI!B11 | C11: =DATI!H11 | D11: =SE.ERRORE(CERCA.X(A11;GIACENZA_REALE!A:A;GIACENZA_REALE!C:C);0) | E11: =SE(C11=0;"";D11/C11) | F11: =MAX(0;ARROTONDA.ECCESSO(C11-D11;1))
A12: =DATI!A12 | B12: =DATI!B12 | C12: =DATI!H12 | D12: =SE.ERRORE(CERCA.X(A12;GIACENZA_REALE!A:A;GIACENZA_REALE!C:C);0) | E12: =SE(C12=0;"";D12/C12) | F12: =MAX(0;ARROTONDA.ECCESSO(C12-D12;1))
A13: =DATI!A13 | B13: =DATI!B13 | C13: =DATI!H13 | D13: =SE.ERRORE(CERCA.X(A13;GIACENZA_REALE!A:A;GIACENZA_REALE!C:C);0) | E13: =SE(C13=0;"";D13/C13) | F13: =MAX(0;ARROTONDA.ECCESSO(C13-D13;1))
... A350: =DATI!A350 | B350: =DATI!B350 | C350: =DATI!H350 | D350: =SE.ERRORE(CERCA.X(A350;GIACENZA_REALE!A:A;GIACENZA_REALE!C:C);0) | E350: =SE(C350=0;"";D350/C350) | F350: =MAX(0;ARROTONDA.ECCESSO(C350-D350;1))

Sheet DASHBOARD
A1: RIEPILOGO ORDINE MENSILE
A3: Prodotti da ordinare: | B3: =CONTA.SE(ORDINE_MESE!F2:F350;">0")
A4: Totale kit da ordinare: | B4: =SOMMA(ORDINE_MESE!F2:F350)
A6: Prodotti critici (<1 mese copertura): | B6: =CONTA.SE(ORDINE_MESE!E2:E350;"<1")
